Workbook

Sheet Registre_Incidents
A1: Registre d’incidents — FAI AllSolutions — DÉMO SYNTHÉTIQUE
A2: Toutes les données de ce fichier sont fictives et destinées aux essais, à la formation et à la démonstration.
A5: ID incident | B5: Date ouverture | C5: Heure | D5: Source plainte | E5: Client / utilisateur | F5: Code client | G5: Site / AP | H5: Équipement impacté | I5: Nature équipement | J5: IP / Accès | K5: Localisation | L5: Catégorie incident | M5: Priorité | N5: SLA heures | O5: Échéance SLA | P5: Responsable | Q5: Statut | R5: Date résolution | S5: Durée heures | T5: SLA respecté | U5: Cause racine | V5: Action corrective | W5: Escalade | X5: Commentaires
A6: Inc-Demo-0001 | B6: 46266.302 | C6: 0.30208333 | D6: Appel | E6: Client Démo Alpha | F6: DEMO-0001 | G6: Site Démo Nord | H6: Routeur-DEMO-01 | I6: Antenne | J6: 10.99.1.20 | K6: Zone Démo A | L6: Internet indisponible | M6: Critique | N6: =IF(M6="","",VLOOKUP(M6,Parametres_SLA!$A$5:$B$8,2,FALSE)) | O6: =IF(B6="","",B6+C6+N6/24) | P6: NOC | Q6: Clôturé | R6: 46266.594 | S6: =IF(B6="","",IF(R6<>"",(R6-(B6+C6))*24,(NOW()-(B6+C6))*24)) | T6: =IF(B6="","",IF(OR(Q6="Résolu",Q6="Clôturé"),IF(R6<=O6,"Oui","Non"),IF(NOW()<=O6,"En cours","En retard"))) | U6: Alimentation instable | V6: Redémarrage contrôlé | W6: Non | X6: Donnée synthétique — aucun client réel.
A7: Inc-Demo-0002 | B7: 46267.099 | C7: 0.098611111 | D7: WhatsApp | E7: Client Démo Bravo | F7: DEMO-0002 | G7: Site Démo Sud | H7: Routeur-DEMO-02 | I7: CPE | J7: 10.99.1.21 | K7: Zone Démo B | L7: Débit lent / instable | M7: Haute | N7: =IF(M7="","",VLOOKUP(M7,Parametres_SLA!$A$5:$B$8,2,FALSE)) | O7: =IF(B7="","",B7+C7+N7/24) | P7: Support niveau 1 | Q7: Résolu | R7: 46267.224 | S7: =IF(B7="","",IF(R7<>"",(R7-(B7+C7))*24,(NOW()-(B7+C7))*24)) | T7: =IF(B7="","",IF(OR(Q7="Résolu",Q7="Clôturé"),IF(R7<=O7,"Oui","Non"),IF(NOW()<=O7,"En cours","En retard"))) | U7: Congestion simulée | V7: Réglage profil | W7: Oui - N2 | X7: Donnée synthétique — aucun client réel.
A8: Inc-Demo-0003 | B8: 46267.895 | C8: 0.89513889 | D8: Email | E8: Client Démo Charlie | F8: DEMO-0003 | G8: Site Démo Est | H8: Routeur-DEMO-03 | I8: CPE | J8: 10.99.1.22 | K8: Zone Démo C | L8: Latence élevée | M8: Moyenne | N8: =IF(M8="","",VLOOKUP(M8,Parametres_SLA!$A$5:$B$8,2,FALSE)) | O8: =IF(B8="","",B8+C8+N8/24) | P8: Support niveau 2 | Q8: Ouvert | S8: =IF(B8="","",IF(R8<>"",(R8-(B8+C8))*24,(NOW()-(B8+C8))*24)) | T8: =IF(B8="","",IF(OR(Q8="Résolu",Q8="Clôturé"),IF(R8<=O8,"Oui","Non"),IF(NOW()<=O8,"En cours","En retard"))) | U8: Configuration CPE | V8: Remplacement préventif | W8: Oui - Terrain | X8: Donnée synthétique — aucun client réel.
A9: Inc-Demo-0004 | B9: 46268.692 | C9: 0.69166667 | D9: Supervision UISP | E9: Client Démo Delta | F9: DEMO-0004 | G9: Site Démo Ouest | H9: Routeur-DEMO-04 | I9: Antenne | J9: 10.99.1.23 | K9: Zone Démo D | L9: Coupure intermittente | M9: Basse | N9: =IF(M9="","",VLOOKUP(M9,Parametres_SLA!$A$5:$B$8,2,FALSE)) | O9: =IF(B9="","",B9+C9+N9/24) | P9: Équipe terrain | Q9: En cours | S9: =IF(B9="","",IF(R9<>"",(R9-(B9+C9))*24,(NOW()-(B9+C9))*24)) | T9: =IF(B9="","",IF(OR(Q9="Résolu",Q9="Clôturé"),IF(R9<=O9,"Oui","Non"),IF(NOW()<=O9,"En cours","En retard"))) | U9: Fibre de desserte | V9: Visite terrain planifiée | W9: Oui - Fournisseur | X9: Donnée synthétique — aucun client réel.
A10: Inc-Demo-0005 | B10: 46269.488 | C10: 0.48819444 | D10: Visite terrain | E10: Client Démo Echo | F10: DEMO-0005 | G10: Site Démo Central | H10: Routeur-DEMO-05 | I10: CPE | J10: 10.99.1.24 | K10: Zone Démo E | L10: Wi-Fi client | M10: Haute | N10: =IF(M10="","",VLOOKUP(M10,Parametres_SLA!$A$5:$B$8,2,FALSE)) | O10: =IF(B10="","",B10+C10+N10/24) | P10: Administration | Q10: Escaladé | S10: =IF(B10="","",IF(R10<>"",(R10-(B10+C10))*24,(NOW()-(B10+C10))*24)) | T10: =IF(B10="","",IF(OR(Q10="Résolu",Q10="Clôturé"),IF(R10<=O10,"Oui","Non"),IF(NOW()<=O10,"En cours","En retard"))) | U10: Redémarrage équipement | V10: Surveillance renforcée | W10: Oui - Direction | X10: Donnée synthétique — aucun client réel.
A11: Inc-Demo-0006 | B11: 46270.285 | C11: 0.28472222 | D11: Autre | E11: Client Démo Foxtrot | F11: DEMO-0006 | G11: Site Démo Nord | H11: Routeur-DEMO-06 | I11: CPE | J11: 10.99.1.25 | K11: Zone Démo A | L11: Équipement hors ligne | M11: Moyenne | N11: =IF(M11="","",VLOOKUP(M11,Parametres_SLA!$A$5:$B$8,2,FALSE)) | O11: =IF(B11="","",B11+C11+N11/24) | P11: À assigner | Q11: En attente client | S11: =IF(B11="","",IF(R11<>"",(R11-(B11+C11))*24,(NOW()-(B11+C11))*24)) | T11: =IF(B11="","",IF(OR(Q11="Résolu",Q11="Clôturé"),IF(R11<=O11,"Oui","Non"),IF(NOW()<=O11,"En cours","En retard"))) | U11: Alimentation instable | V11: Redémarrage contrôlé | W11: Non | X11: Donnée synthétique — aucun client réel.
A12: Inc-Demo-0007 | B12: 46271.081 | C12: 0.08125 | D12: Appel | E12: Client Démo Golf | F12: DEMO-0007 | G12: Site Démo Sud | H12: Routeur-DEMO-07 | I12: Antenne | J12: 10.99.1.26 | K12: Zone Démo B | L12: Problème alimentation | M12: Critique | N12: =IF(M12="","",VLOOKUP(M12,Parametres_SLA!$A$5:$B$8,2,FALSE)) | O12: =IF(B12="","",B12+C12+N12/24) | P12: NOC | Q12: Clôturé | R12: 46271.206 | S12: =IF(B12="","",IF(R12<>"",(R12-(B12+C12))*24,(NOW()-(B12+C12))*24)) | T12: =IF(B12="","",IF(OR(Q12="Résolu",Q12="Clôturé"),IF(R12<=O12,"Oui","Non"),IF(NOW()<=O12,"En cours","En retard"))) | U12: Congestion simulée | V12: Réglage profil | W12: Oui - N2 | X12: Donnée synthétique — aucun client réel.
A13: Inc-Demo-0008 | B13: 46271.878 | C13: 0.87777778 | D13: WhatsApp | E13: Client Démo Hotel | F13: DEMO-0008 | G13: Site Démo Est | H13: Routeur-DEMO-08 | I13: CPE | J13: 10.99.1.27 | K13: Zone Démo C | L13: Configuration / accès | M13: Basse | N13: =IF(M13="","",VLOOKUP(M13,Parametres_SLA!$A$5:$B$8,2,FALSE)) | O13: =IF(B13="","",B13+C13+N13/24) | P13: Support niveau 1 | Q13: Résolu | R13: 46272.044 | S13: =IF(B13="","",IF(R13<>"",(R13-(B13+C13))*24,(NOW()-(B13+C13))*24)) | T13: =IF(B13="","",IF(OR(Q13="Résolu",Q13="Clôturé"),IF(R13<=O13,"Oui","Non"),IF(NOW()<=O13,"En cours","En retard"))) | U13: Configuration CPE | V13: Remplacement préventif | W13: Oui - Terrain | X13: Donnée synthétique — aucun client réel.
A14: Inc-Demo-0009 | B14: 46272.674 | C14: 0.67430556 | D14: Email | E14: Client Démo India | F14: DEMO-0009 | G14: Site Démo Ouest | H14: Routeur-DEMO-01 | I14: CPE | J14: 10.99.1.28 | K14: Zone Démo D | L14: Facturation liée au service | M14: Moyenne | N14: =IF(M14="","",VLOOKUP(M14,Parametres_SLA!$A$5:$B$8,2,FALSE)) | O14: =IF(B14="","",B14+C14+N14/24) | P14: Support niveau 2 | Q14: En cours | S14: =IF(B14="","",IF(R14<>"",(R14-(B14+C14))*24,(NOW()-(B14+C14))*24)) | T14: =IF(B14="","",IF(OR(Q14="Résolu",Q14="Clôturé"),IF(R14<=O14,"Oui","Non"),IF(NOW()<=O14,"En cours","En retard"))) | U14: Fibre de desserte | V14: Visite terrain planifiée | W14: Oui - Fournisseur | X14: Donnée synthétique — aucun client réel.
A15: Inc-Demo-0010 | B15: 46273.429 | C15: 0.42916667 | D15: Supervision UISP | E15: Client Démo Juliett | F15: DEMO-0010 | G15: Site Démo Central | H15: Routeur-DEMO-02 | I15: Antenne | J15: 10.99.1.29 | K15: Zone Démo E | L15: Autre | M15: Haute | N15: =IF(M15="","",VLOOKUP(M15,Parametres_SLA!$A$5:$B$8,2,FALSE)) | O15: =IF(B15="","",B15+C15+N15/24) | P15: Équipe terrain | Q15: Ouvert | S15: =IF(B15="","",IF(R15<>"",(R15-(B15+C15))*24,(NOW()-(B15+C15))*24)) | T15: =IF(B15="","",IF(OR(Q15="Résolu",Q15="Clôturé"),IF(R15<=O15,"Oui","Non"),IF(NOW()<=O15,"En cours","En retard"))) | U15: Redémarrage équipement | V15: Surveillance renforcée | W15: Oui - Direction | X15: Donnée synthétique — aucun client réel.
A16: Inc-Demo-0011 | B16: 46274.226 | C16: 0.22569444 | D16: Visite terrain | E16: Client Démo Kilo | F16: DEMO-0011 | G16: Site Démo Nord | H16: Routeur-DEMO-03 | I16: CPE | J16: 10.99.2.30 | K16: Zone Démo A | L16: Internet indisponible | M16: Critique | N16: =IF(M16="","",VLOOKUP(M16,Parametres_SLA!$A$5:$B$8,2,FALSE)) | O16: =IF(B16="","",B16+C16+N16/24) | P16: Administration | Q16: Clôturé | R16: 46274.309 | S16: =IF(B16="","",IF(R16<>"",(R16-(B16+C16))*24,(NOW()-(B16+C16))*24)) | T16: =IF(B16="","",IF(OR(Q16="Résolu",Q16="Clôturé"),IF(R16<=O16,"Oui","Non"),IF(NOW()<=O16,"En cours","En retard"))) | U16: Alimentation instable | V16: Redémarrage contrôlé | W16: Non | X16: Donnée synthétique — aucun client réel.
A17: Inc-Demo-0012 | B17: 46275.022 | C17: 0.022222222 | D17: Autre | E17: Client Démo Lima | F17: DEMO-0012 | G17: Site Démo Sud | H17: Routeur-DEMO-04 | I17: CPE | J17: 10.99.2.31 | K17: Zone Démo B | L17: Débit lent / instable | M17: Haute | N17: =IF(M17="","",VLOOKUP(M17,Parametres_SLA!$A$5:$B$8,2,FALSE)) | O17: =IF(B17="","",B17+C17+N17/24) | P17: À assigner | Q17: Résolu | R17: 46275.147 | S17: =IF(B17="","",IF(R17<>"",(R17-(B17+C17))*24,(NOW()-(B17+C17))*24)) | T17: =IF(B17="","",IF(OR(Q17="Résolu",Q17="Clôturé"),IF(R17<=O17,"Oui","Non"),IF(NOW()<=O17,"En cours","En retard"))) | U17: Congestion simulée | V17: Réglage profil | W17: Oui - N2 | X17: Donnée synthétique — aucun client réel.
A18: Inc-Demo-0013 | B18: 46275.819 | C18: 0.81875 | D18: Appel | E18: Client Démo Mike | F18: DEMO-0013 | G18: Site Démo Est | H18: Routeur-DEMO-05 | I18: Antenne | J18: 10.99.2.32 | K18: Zone Démo C | L18: Latence élevée | M18: Moyenne | N18: =IF(M18="","",VLOOKUP(M18,Parametres_SLA!$A$5:$B$8,2,FALSE)) | O18: =IF(B18="","",B18+C18+N18/24) | P18: NOC | Q18: Ouvert | S18: =IF(B18="","",IF(R18<>"",(R18-(B18+C18))*24,(NOW()-(B18+C18))*24)) | T18: =IF(B18="","",IF(OR(Q18="Résolu",Q18="Clôturé"),IF(R18<=O18,"Oui","Non"),IF(NOW()<=O18,"En cours","En retard"))) | U18: Configuration CPE | V18: Remplacement préventif | W18: Oui - Terrain | X18: Donnée synthétique — aucun client réel.
A19: Inc-Demo-0014 | B19: 46276.615 | C19: 0.61527778 | D19: WhatsApp | E19: Client Démo November | F19: DEMO-0014 | G19: Site Démo Ouest | H19: Routeur-DEMO-06 | I19: CPE | J19: 10.99.2.33 | K19: Zone Démo D | L19: Coupure intermittente | M19: Basse | N19: =IF(M19="","",VLOOKUP(M19,Parametres_SLA!$A$5:$B$8,2,FALSE)) | O19: =IF(B19="","",B19+C19+N19/24) | P19: Support niveau 1 | Q19: En cours | S19: =IF(B19="","",IF(R19<>"",(R19-(B19+C19))*24,(NOW()-(B19+C19))*24)) | T19: =IF(B19="","",IF(OR(Q19="Résolu",Q19="Clôturé"),IF(R19<=O19,"Oui","Non"),IF(NOW()<=O19,"En cours","En retard"))) | U19: Fibre de desserte | V19: Visite terrain planifiée | W19: Oui - Fournisseur | X19: Donnée synthétique — aucun client réel.
A20: Inc-Demo-0015 | B20: 46277.412 | C20: 0.41180556 | D20: Email | E20: Client Démo Oscar | F20: DEMO-0015 | G20: Site Démo Central | H20: Routeur-DEMO-07 | I20: CPE | J20: 10.99.2.34 | K20: Zone Démo E | L20: Wi-Fi client | M20: Haute | N20: =IF(M20="","",VLOOKUP(M20,Parametres_SLA!$A$5:$B$8,2,FALSE)) | O20: =IF(B20="","",B20+C20+N20/24) | P20: Support niveau 2 | Q20: Escaladé | S20: =IF(B20="","",IF(R20<>"",(R20-(B20+C20))*24,(NOW()-(B20+C20))*24)) | T20: =IF(B20="","",IF(OR(Q20="Résolu",Q20="Clôturé"),IF(R20<=O20,"Oui","Non"),IF(NOW()<=O20,"En cours","En retard"))) | U20: Redémarrage équipement | V20: Surveillance renforcée | W20: Oui - Direction | X20: Donnée synthétique — aucun client réel.
A21: Inc-Demo-0016 | B21: 46278.208 | C21: 0.20833333 | D21: Supervision UISP | E21: Client Démo Papa | F21: DEMO-0016 | G21: Site Démo Nord | H21: Routeur-DEMO-08 | I21: Antenne | J21: 10.99.2.35 | K21: Zone Démo A | L21: Équipement hors ligne | M21: Moyenne | N21: =IF(M21="","",VLOOKUP(M21,Parametres_SLA!$A$5:$B$8,2,FALSE)) | O21: =IF(B21="","",B21+C21+N21/24) | P21: Équipe terrain | Q21: En attente client | S21: =IF(B21="","",IF(R21<>"",(R21-(B21+C21))*24,(NOW()-(B21+C21))*24)) | T21: =IF(B21="","",IF(OR(Q21="Résolu",Q21="Clôturé"),IF(R21<=O21,"Oui","Non"),IF(NOW()<=O21,"En cours","En retard"))) | U21: Alimentation instable | V21: Redémarrage contrôlé | W21: Non | X21: Donnée synthétique — aucun client réel.
A22: Inc-Demo-0017 | B22: 46279.005 | C22: 0.0048611111 | D22: Visite terrain | E22: Client Démo Quebec | F22: DEMO-0017 | G22: Site Démo Sud | H22: Routeur-DEMO-01 | I22: CPE | J22: 10.99.2.36 | K22: Zone Démo B | L22: Problème alimentation | M22: Critique | N22: =IF(M22="","",VLOOKUP(M22,Parametres_SLA!$A$5:$B$8,2,FALSE)) | O22: =IF(B22="","",B22+C22+N22/24) | P22: Administration | Q22: Clôturé | R22: 46279.297 | S22: =IF(B22="","",IF(R22<>"",(R22-(B22+C22))*24,(NOW()-(B22+C22))*24)) | T22: =IF(B22="","",IF(OR(Q22="Résolu",Q22="Clôturé"),IF(R22<=O22,"Oui","Non"),IF(NOW()<=O22,"En cours","En retard"))) | U22: Congestion simulée | V22: Réglage profil | W22: Oui - N2 | X22: Donnée synthétique — aucun client réel.
A23: Inc-Demo-0018 | B23: 46279.801 | C23: 0.80138889 | D23: Autre | E23: Client Démo Romeo | F23: DEMO-0018 | G23: Site Démo Est | H23: Routeur-DEMO-02 | I23: CPE | J23: 10.99.2.37 | K23: Zone Démo C | L23: Configuration / accès | M23: Basse | N23: =IF(M23="","",VLOOKUP(M23,Parametres_SLA!$A$5:$B$8,2,FALSE)) | O23: =IF(B23="","",B23+C23+N23/24) | P23: À assigner | Q23: Résolu | R23: 46279.968 | S23: =IF(B23="","",IF(R23<>"",(R23-(B23+C23))*24,(NOW()-(B23+C23))*24)) | T23: =IF(B23="","",IF(OR(Q23="Résolu",Q23="Clôturé"),IF(R23<=O23,"Oui","Non"),IF(NOW()<=O23,"En cours","En retard"))) | U23: Configuration CPE | V23: Remplacement préventif | W23: Oui - Terrain | X23: Donnée synthétique — aucun client réel.
A24: Inc-Demo-0019 | B24: 46280.556 | C24: 0.55625 | D24: Appel | E24: Client Démo Sierra | F24: DEMO-0019 | G24: Site Démo Ouest | H24: Routeur-DEMO-03 | I24: Antenne | J24: 10.99.2.38 | K24: Zone Démo D | L24: Facturation liée au service | M24: Moyenne | N24: =IF(M24="","",VLOOKUP(M24,Parametres_SLA!$A$5:$B$8,2,FALSE)) | O24: =IF(B24="","",B24+C24+N24/24) | P24: NOC | Q24: En cours | S24: =IF(B24="","",IF(R24<>"",(R24-(B24+C24))*24,(NOW()-(B24+C24))*24)) | T24: =IF(B24="","",IF(OR(Q24="Résolu",Q24="Clôturé"),IF(R24<=O24,"Oui","Non"),IF(NOW()<=O24,"En cours","En retard"))) | U24: Fibre de desserte | V24: Visite terrain planifiée | W24: Oui - Fournisseur | X24: Donnée synthétique — aucun client réel.
A25: Inc-Demo-0020 | B25: 46281.353 | C25: 0.35277778 | D25: WhatsApp | E25: Client Démo Tango | F25: DEMO-0020 | G25: Site Démo Central | H25: Routeur-DEMO-04 | I25: CPE | J25: 10.99.2.39 | K25: Zone Démo E | L25: Autre | M25: Haute | N25: =IF(M25="","",VLOOKUP(M25,Parametres_SLA!$A$5:$B$8,2,FALSE)) | O25: =IF(B25="","",B25+C25+N25/24) | P25: Support niveau 1 | Q25: Ouvert | S25: =IF(B25="","",IF(R25<>"",(R25-(B25+C25))*24,(NOW()-(B25+C25))*24)) | T25: =IF(B25="","",IF(OR(Q25="Résolu",Q25="Clôturé"),IF(R25<=O25,"Oui","Non"),IF(NOW()<=O25,"En cours","En retard"))) | U25: Redémarrage équipement | V25: Surveillance renforcée | W25: Oui - Direction | X25: Donnée synthétique — aucun client réel.
A26: Inc-Demo-0021 | B26: 46282.149 | C26: 0.14930556 | D26: Email | E26: Client Démo Uniform | F26: DEMO-0021 | G26: Site Démo Nord | H26: Routeur-DEMO-05 | I26: CPE | J26: 10.99.3.40 | K26: Zone Démo A | L26: Internet indisponible | M26: Critique | N26: =IF(M26="","",VLOOKUP(M26,Parametres_SLA!$A$5:$B$8,2,FALSE)) | O26: =IF(B26="","",B26+C26+N26/24) | P26: Support niveau 2 | Q26: Clôturé | R26: 46282.441 | S26: =IF(B26="","",IF(R26<>"",(R26-(B26+C26))*24,(NOW()-(B26+C26))*24)) | T26: =IF(B26="","",IF(OR(Q26="Résolu",Q26="Clôturé"),IF(R26<=O26,"Oui","Non"),IF(NOW()<=O26,"En cours","En retard"))) | U26: Alimentation instable | V26: Redémarrage contrôlé | W26: Non | X26: Donnée synthétique — aucun client réel.
A27: Inc-Demo-0022 | B27: 46282.946 | C27: 0.94583333 | D27: Supervision UISP | E27: Client Démo Victor | F27: DEMO-0022 | G27: Site Démo Sud | H27: Routeur-DEMO-06 | I27: Antenne | J27: 10.99.3.41 | K27: Zone Démo B | L27: Débit lent / instable | M27: Haute | N27: =IF(M27="","",VLOOKUP(M27,Parametres_SLA!$A$5:$B$8,2,FALSE)) | O27: =IF(B27="","",B27+C27+N27/24) | P27: Équipe terrain | Q27: Résolu | R27: 46283.071 | S27: =IF(B27="","",IF(R27<>"",(R27-(B27+C27))*24,(NOW()-(B27+C27))*24)) | T27: =IF(B27="","",IF(OR(Q27="Résolu",Q27="Clôturé"),IF(R27<=O27,"Oui","Non"),IF(NOW()<=O27,"En cours","En retard"))) | U27: Congestion simulée | V27: Réglage profil | W27: Oui - N2 | X27: Donnée synthétique — aucun client réel.
A28: Inc-Demo-0023 | B28: 46283.742 | C28: 0.74236111 | D28: Visite terrain | E28: Client Démo Whiskey | F28: DEMO-0023 | G28: Site Démo Est | H28: Routeur-DEMO-07 | I28: CPE | J28: 10.99.3.42 | K28: Zone Démo C | L28: Latence élevée | M28: Moyenne | N28: =IF(M28="","",VLOOKUP(M28,Parametres_SLA!$A$5:$B$8,2,FALSE)) | O28: =IF(B28="","",B28+C28+N28/24) | P28: Administration | Q28: Ouvert | S28: =IF(B28="","",IF(R28<>"",(R28-(B28+C28))*24,(NOW()-(B28+C28))*24)) | T28: =IF(B28="","",IF(OR(Q28="Résolu",Q28="Clôturé"),IF(R28<=O28,"Oui","Non"),IF(NOW()<=O28,"En cours","En retard"))) | U28: Configuration CPE | V28: Remplacement préventif | W28: Oui - Terrain | X28: Donnée synthétique — aucun client réel.
A29: Inc-Demo-0024 | B29: 46284.539 | C29: 0.53888889 | D29: Autre | E29: Client Démo Xray | F29: DEMO-0024 | G29: Site Démo Ouest | H29: Routeur-DEMO-08 | I29: CPE | J29: 10.99.3.43 | K29: Zone Démo D | L29: Coupure intermittente | M29: Basse | N29: =IF(M29="","",VLOOKUP(M29,Parametres_SLA!$A$5:$B$8,2,FALSE)) | O29: =IF(B29="","",B29+C29+N29/24) | P29: À assigner | Q29: En cours | S29: =IF(B29="","",IF(R29<>"",(R29-(B29+C29))*24,(NOW()-(B29+C29))*24)) | T29: =IF(B29="","",IF(OR(Q29="Résolu",Q29="Clôturé"),IF(R29<=O29,"Oui","Non"),IF(NOW()<=O29,"En cours","En retard"))) | U29: Fibre de desserte | V29: Visite terrain planifiée | W29: Oui - Fournisseur | X29: Donnée synthétique — aucun client réel.
A30: Inc-Demo-0025 | B30: 46285.335 | C30: 0.33541667 | D30: Appel | E30: Client Démo Yankee | F30: DEMO-0025 | G30: Site Démo Central | H30: Routeur-DEMO-01 | I30: Antenne | J30: 10.99.3.44 | K30: Zone Démo E | L30: Wi-Fi client | M30: Haute | N30: =IF(M30="","",VLOOKUP(M30,Parametres_SLA!$A$5:$B$8,2,FALSE)) | O30: =IF(B30="","",B30+C30+N30/24) | P30: NOC | Q30: Escaladé | S30: =IF(B30="","",IF(R30<>"",(R30-(B30+C30))*24,(NOW()-(B30+C30))*24)) | T30: =IF(B30="","",IF(OR(Q30="Résolu",Q30="Clôturé"),IF(R30<=O30,"Oui","Non"),IF(NOW()<=O30,"En cours","En retard"))) | U30: Redémarrage équipement | V30: Surveillance renforcée | W30: Oui - Direction | X30: Donnée synthétique — aucun client réel.
A31: Inc-Demo-0026 | B31: 46286.132 | C31: 0.13194444 | D31: WhatsApp | E31: Client Démo Zulu | F31: DEMO-0026 | G31: Site Démo Nord | H31: Routeur-DEMO-02 | I31: CPE | J31: 10.99.3.45 | K31: Zone Démo A | L31: Équipement hors ligne | M31: Moyenne | N31: =IF(M31="","",VLOOKUP(M31,Parametres_SLA!$A$5:$B$8,2,FALSE)) | O31: =IF(B31="","",B31+C31+N31/24) | P31: Support niveau 1 | Q31: En attente client | S31: =IF(B31="","",IF(R31<>"",(R31-(B31+C31))*24,(NOW()-(B31+C31))*24)) | T31: =IF(B31="","",IF(OR(Q31="Résolu",Q31="Clôturé"),IF(R31<=O31,"Oui","Non"),IF(NOW()<=O31,"En cours","En retard"))) | U31: Alimentation instable | V31: Redémarrage contrôlé | W31: Non | X31: Donnée synthétique — aucun client réel.
A32: Inc-Demo-0027 | B32: 46286.887 | C32: 0.88680556 | D32: Email | E32: Client Démo Atlas | F32: DEMO-0027 | G32: Site Démo Sud | H32: Routeur-DEMO-03 | I32: CPE | J32: 10.99.3.46 | K32: Zone Démo B | L32: Problème alimentation | M32: Critique | N32: =IF(M32="","",VLOOKUP(M32,Parametres_SLA!$A$5:$B$8,2,FALSE)) | O32: =IF(B32="","",B32+C32+N32/24) | P32: Support niveau 2 | Q32: Clôturé | R32: 46287.012 | S32: =IF(B32="","",IF(R32<>"",(R32-(B32+C32))*24,(NOW()-(B32+C32))*24)) | T32: =IF(B32="","",IF(OR(Q32="Résolu",Q32="Clôturé"),IF(R32<=O32,"Oui","Non"),IF(NOW()<=O32,"En cours","En retard"))) | U32: Congestion simulée | V32: Réglage profil | W32: Oui - N2 | X32: Donnée synthétique — aucun client réel.
A33: Inc-Demo-0028 | B33: 46287.683 | C33: 0.68333333 | D33: Supervision UISP | E33: Client Démo Nova | F33: DEMO-0028 | G33: Site Démo Est | H33: Routeur-DEMO-04 | I33: Antenne | J33: 10.99.3.47 | K33: Zone Démo C | L33: Configuration / accès | M33: Basse | N33: =IF(M33="","",VLOOKUP(M33,Parametres_SLA!$A$5:$B$8,2,FALSE)) | O33: =IF(B33="","",B33+C33+N33/24) | P33: Équipe terrain | Q33: Résolu | R33: 46287.85 | S33: =IF(B33="","",IF(R33<>"",(R33-(B33+C33))*24,(NOW()-(B33+C33))*24)) | T33: =IF(B33="","",IF(OR(Q33="Résolu",Q33="Clôturé"),IF(R33<=O33,"Oui","Non"),IF(NOW()<=O33,"En cours","En retard"))) | U33: Configuration CPE | V33: Remplacement préventif | W33: Oui - Terrain | X33: Donnée synthétique — aucun client réel.
A34: Inc-Demo-0029 | B34: 46288.48 | C34: 0.47986111 | D34: Visite terrain | E34: Client Démo Orion | F34: DEMO-0029 | G34: Site Démo Ouest | H34: Routeur-DEMO-05 | I34: CPE | J34: 10.99.3.48 | K34: Zone Démo D | L34: Facturation liée au service | M34: Moyenne | N34: =IF(M34="","",VLOOKUP(M34,Parametres_SLA!$A$5:$B$8,2,FALSE)) | O34: =IF(B34="","",B34+C34+N34/24) | P34: Administration | Q34: En cours | S34: =IF(B34="","",IF(R34<>"",(R34-(B34+C34))*24,(NOW()-(B34+C34))*24)) | T34: =IF(B34="","",IF(OR(Q34="Résolu",Q34="Clôturé"),IF(R34<=O34,"Oui","Non"),IF(NOW()<=O34,"En cours","En retard"))) | U34: Fibre de desserte | V34: Visite terrain planifiée | W34: Oui - Fournisseur | X34: Donnée synthétique — aucun client réel.
A35: Inc-Demo-0030 | B35: 46289.276 | C35: 0.27638889 | D35: Autre | E35: Client Démo Vega | F35: DEMO-0030 | G35: Site Démo Central | H35: Routeur-DEMO-06 | I35: CPE | J35: 10.99.3.49 | K35: Zone Démo E | L35: Autre | M35: Haute | N35: =IF(M35="","",VLOOKUP(M35,Parametres_SLA!$A$5:$B$8,2,FALSE)) | O35: =IF(B35="","",B35+C35+N35/24) | P35: À assigner | Q35: Ouvert | S35: =IF(B35="","",IF(R35<>"",(R35-(B35+C35))*24,(NOW()-(B35+C35))*24)) | T35: =IF(B35="","",IF(OR(Q35="Résolu",Q35="Clôturé"),IF(R35<=O35,"Oui","Non"),IF(NOW()<=O35,"En cours","En retard"))) | U35: Redémarrage équipement | V35: Surveillance renforcée | W35: Oui - Direction | X35: Donnée synthétique — aucun client réel.
A36: =IF(B36="","","Inc-Demo-"&TEXT(ROW()-5,"0000")) | N36: =IF(M36="","",VLOOKUP(M36,Parametres_SLA!$A$5:$B$8,2,FALSE)) | O36: =IF(B36="","",B36+C36+N36/24) | S36: =IF(B36="","",IF(R36<>"",(R36-(B36+C36))*24,(NOW()-(B36+C36))*24)) | T36: =IF(B36="","",IF(OR(Q36="Résolu",Q36="Clôturé"),IF(R36<=O36,"Oui","Non"),IF(NOW()<=O36,"En cours","En retard")))
A37: =IF(B37="","","Inc-Demo-"&TEXT(ROW()-5,"0000")) | N37: =IF(M37="","",VLOOKUP(M37,Parametres_SLA!$A$5:$B$8,2,FALSE)) | O37: =IF(B37="","",B37+C37+N37/24) | S37: =IF(B37="","",IF(R37<>"",(R37-(B37+C37))*24,(NOW()-(B37+C37))*24)) | T37: =IF(B37="","",IF(OR(Q37="Résolu",Q37="Clôturé"),IF(R37<=O37,"Oui","Non"),IF(NOW()<=O37,"En cours","En retard")))
A38: =IF(B38="","","Inc-Demo-"&TEXT(ROW()-5,"0000")) | N38: =IF(M38="","",VLOOKUP(M38,Parametres_SLA!$A$5:$B$8,2,FALSE)) | O38: =IF(B38="","",B38+C38+N38/24) | S38: =IF(B38="","",IF(R38<>"",(R38-(B38+C38))*24,(NOW()-(B38+C38))*24)) | T38: =IF(B38="","",IF(OR(Q38="Résolu",Q38="Clôturé"),IF(R38<=O38,"Oui","Non"),IF(NOW()<=O38,"En cours","En retard")))
A39: =IF(B39="","","Inc-Demo-"&TEXT(ROW()-5,"0000")) | N39: =IF(M39="","",VLOOKUP(M39,Parametres_SLA!$A$5:$B$8,2,FALSE)) | O39: =IF(B39="","",B39+C39+N39/24) | S39: =IF(B39="","",IF(R39<>"",(R39-(B39+C39))*24,(NOW()-(B39+C39))*24)) | T39: =IF(B39="","",IF(OR(Q39="Résolu",Q39="Clôturé"),IF(R39<=O39,"Oui","Non"),IF(NOW()<=O39,"En cours","En retard")))
A40: =IF(B40="","","Inc-Demo-"&TEXT(ROW()-5,"0000")) | N40: =IF(M40="","",VLOOKUP(M40,Parametres_SLA!$A$5:$B$8,2,FALSE)) | O40: =IF(B40="","",B40+C40+N40/24) | S40: =IF(B40="","",IF(R40<>"",(R40-(B40+C40))*24,(NOW()-(B40+C40))*24)) | T40: =IF(B40="","",IF(OR(Q40="Résolu",Q40="Clôturé"),IF(R40<=O40,"Oui","Non"),IF(NOW()<=O40,"En cours","En retard")))
A41: =IF(B41="","","Inc-Demo-"&TEXT(ROW()-5,"0000")) | N41: =IF(M41="","",VLOOKUP(M41,Parametres_SLA!$A$5:$B$8,2,FALSE)) | O41: =IF(B41="","",B41+C41+N41/24) | S41: =IF(B41="","",IF(R41<>"",(R41-(B41+C41))*24,(NOW()-(B41+C41))*24)) | T41: =IF(B41="","",IF(OR(Q41="Résolu",Q41="Clôturé"),IF(R41<=O41,"Oui","Non"),IF(NOW()<=O41,"En cours","En retard")))
A42: =IF(B42="","","Inc-Demo-"&TEXT(ROW()-5,"0000")) | N42: =IF(M42="","",VLOOKUP(M42,Parametres_SLA!$A$5:$B$8,2,FALSE)) | O42: =IF(B42="","",B42+C42+N42/24) | S42: =IF(B42="","",IF(R42<>"",(R42-(B42+C42))*24,(NOW()-(B42+C42))*24)) | T42: =IF(B42="","",IF(OR(Q42="Résolu",Q42="Clôturé"),IF(R42<=O42,"Oui","Non"),IF(NOW()<=O42,"En cours","En retard")))
...

Sheet Tableau_de_bord
A1: FAI AllSolutions — Tableau de bord opérationnel — DÉMO
A2: Indicateurs basés exclusivement sur les données synthétiques du registre.
A4: Total incidents | D4: Ouverts | G4: Critiques | J4: SLA en retard
A5: =COUNTIF(Registre_Incidents!$B$6:$B$205,"<>") | D5: =COUNTIFS(Registre_Incidents!$B$6:$B$205,"<>",Registre_Incidents!$Q$6:$Q$205,"<>Résolu",Registre_Incidents!$Q$6:$Q$205,"<>Clôturé") | G5: =COUNTIFS(Registre_Incidents!$B$6:$B$205,"<>",Registre_Incidents!$M$6:$M$205,"Critique") | J5: =COUNTIF(Registre_Incidents!$T$6:$T$205,"En retard")
A8: Taux respect SLA | D8: Durée moyenne (h) | G8: Résolus / clôturés | J8: Escaladés
A9: =IFERROR(COUNTIF(Registre_Incidents!$T$6:$T$205,"Oui")/(COUNTIF(Registre_Incidents!$T$6:$T$205,"Oui")+COUNTIF(Registre_Incidents!$T$6:$T$205,"Non")),0) | D9: =IFERROR(AVERAGEIF(Registre_Incidents!$S$6:$S$205,">0"),0) | G9: =COUNTIF(Registre_Incidents!$Q$6:$Q$205,"Résolu")+COUNTIF(Registre_Incidents!$Q$6:$Q$205,"Clôturé") | J9: =COUNTIFS(Registre_Incidents!$B$6:$B$205,"<>",Registre_Incidents!$W$6:$W$205,"<>Non",Registre_Incidents!$W$6:$W$205,"<>")
A13: Statut | B13: Nombre | D13: Priorité | E13: Nombre | G13: Rappel
A14: Ouvert | B14: =COUNTIF(Registre_Incidents!$Q$6:$Q$205,A14) | D14: Critique | E14: =COUNTIF(Registre_Incidents!$M$6:$M$205,D14) | G14: Données 100% fictives
A15: En cours | B15: =COUNTIF(Registre_Incidents!$Q$6:$Q$205,A15) | D15: Haute | E15: =COUNTIF(Registre_Incidents!$M$6:$M$205,D15) | G15: Aucun client réel
A16: En attente client | B16: =COUNTIF(Registre_Incidents!$Q$6:$Q$205,A16) | D16: Moyenne | E16: =COUNTIF(Registre_Incidents!$M$6:$M$205,D16) | G16: Utiliser pour formation / test
A17: Escaladé | B17: =COUNTIF(Registre_Incidents!$Q$6:$Q$205,A17) | D17: Basse | E17: =COUNTIF(Registre_Incidents!$M$6:$M$205,D17)
A18: Résolu | B18: =COUNTIF(Registre_Incidents!$Q$6:$Q$205,A18)
A19: Derniers incidents | B19: =COUNTIF(Registre_Incidents!$Q$6:$Q$205,A19)
A20: ID | B20: Date ouverture | C20: Client | D20: Catégorie | E20: Priorité | F20: Statut | G20: SLA | H20: Responsable
A21: =IF(Registre_Incidents!A6="","",Registre_Incidents!A6) | B21: =IF(Registre_Incidents!A6="","",Registre_Incidents!B6) | C21: =IF(Registre_Incidents!A6="","",Registre_Incidents!E6) | D21: =IF(Registre_Incidents!A6="","",Registre_Incidents!L6) | E21: =IF(Registre_Incidents!A6="","",Registre_Incidents!M6) | F21: =IF(Registre_Incidents!A6="","",Registre_Incidents!Q6) | G21: =IF(Registre_Incidents!A6="","",Registre_Incidents!T6) | H21: =IF(Registre_Incidents!A6="","",Registre_Incidents!P6)
A22: =IF(Registre_Incidents!A7="","",Registre_Incidents!A7) | B22: =IF(Registre_Incidents!A7="","",Registre_Incidents!B7) | C22: =IF(Registre_Incidents!A7="","",Registre_Incidents!E7) | D22: =IF(Registre_Incidents!A7="","",Registre_Incidents!L7) | E22: =IF(Registre_Incidents!A7="","",Registre_Incidents!M7) | F22: =IF(Registre_Incidents!A7="","",Registre_Incidents!Q7) | G22: =IF(Registre_Incidents!A7="","",Registre_Incidents!T7) | H22: =IF(Registre_Incidents!A7="","",Registre_Incidents!P7)
A23: =IF(Registre_Incidents!A8="","",Registre_Incidents!A8) | B23: =IF(Registre_Incidents!A8="","",Registre_Incidents!B8) | C23: =IF(Registre_Incidents!A8="","",Registre_Incidents!E8) | D23: =IF(Registre_Incidents!A8="","",Registre_Incidents!L8) | E23: =IF(Registre_Incidents!A8="","",Registre_Incidents!M8) | F23: =IF(Registre_Incidents!A8="","",Registre_Incidents!Q8) | G23: =IF(Registre_Incidents!A8="","",Registre_Incidents!T8) | H23: =IF(Registre_Incidents!A8="","",Registre_Incidents!P8)
A24: =IF(Registre_Incidents!A9="","",Registre_Incidents!A9) | B24: =IF(Registre_Incidents!A9="","",Registre_Incidents!B9) | C24: =IF(Registre_Incidents!A9="","",Registre_Incidents!E9) | D24: =IF(Registre_Incidents!A9="","",Registre_Incidents!L9) | E24: =IF(Registre_Incidents!A9="","",Registre_Incidents!M9) | F24: =IF(Registre_Incidents!A9="","",Registre_Incidents!Q9) | G24: =IF(Registre_Incidents!A9="","",Registre_Incidents!T9) | H24: =IF(Registre_Incidents!A9="","",Registre_Incidents!P9)
A25: =IF(Registre_Incidents!A10="","",Registre_Incidents!A10) | B25: =IF(Registre_Incidents!A10="","",Registre_Incidents!B10) | C25: =IF(Registre_Incidents!A10="","",Registre_Incidents!E10) | D25: =IF(Registre_Incidents!A10="","",Registre_Incidents!L10) | E25: =IF(Registre_Incidents!A10="","",Registre_Incidents!M10) | F25: =IF(Registre_Incidents!A10="","",Registre_Incidents!Q10) | G25: =IF(Registre_Incidents!A10="","",Registre_Incidents!T10) | H25: =IF(Registre_Incidents!A10="","",Registre_Incidents!P10)
A26: =IF(Registre_Incidents!A11="","",Registre_Incidents!A11) | B26: =IF(Registre_Incidents!A11="","",Registre_Incidents!B11) | C26: =IF(Registre_Incidents!A11="","",Registre_Incidents!E11) | D26: =IF(Registre_Incidents!A11="","",Registre_Incidents!L11) | E26: =IF(Registre_Incidents!A11="","",Registre_Incidents!M11) | F26: =IF(Registre_Incidents!A11="","",Registre_Incidents!Q11) | G26: =IF(Registre_Incidents!A11="","",Registre_Incidents!T11) | H26: =IF(Registre_Incidents!A11="","",Registre_Incidents!P11)
A27: =IF(Registre_Incidents!A12="","",Registre_Incidents!A12) | B27: =IF(Registre_Incidents!A12="","",Registre_Incidents!B12) | C27: =IF(Registre_Incidents!A12="","",Registre_Incidents!E12) | D27: =IF(Registre_Incidents!A12="","",Registre_Incidents!L12) | E27: =IF(Registre_Incidents!A12="","",Registre_Incidents!M12) | F27: =IF(Registre_Incidents!A12="","",Registre_Incidents!Q12) | G27: =IF(Registre_Incidents!A12="","",Registre_Incidents!T12) | H27: =IF(Registre_Incidents!A12="","",Registre_Incidents!P12)
A28: =IF(Registre_Incidents!A13="","",Registre_Incidents!A13) | B28: =IF(Registre_Incidents!A13="","",Registre_Incidents!B13) | C28: =IF(Registre_Incidents!A13="","",Registre_Incidents!E13) | D28: =IF(Registre_Incidents!A13="","",Registre_Incidents!L13) | E28: =IF(Registre_Incidents!A13="","",Registre_Incidents!M13) | F28: =IF(Registre_Incidents!A13="","",Registre_Incidents!Q13) | G28: =IF(Registre_Incidents!A13="","",Registre_Incidents!T13) | H28: =IF(Registre_Incidents!A13="","",Registre_Incidents!P13)
A29: =IF(Registre_Incidents!A14="","",Registre_Incidents!A14) | B29: =IF(Registre_Incidents!A14="","",Registre_Incidents!B14) | C29: =IF(Registre_Incidents!A14="","",Registre_Incidents!E14) | D29: =IF(Registre_Incidents!A14="","",Registre_Incidents!L14) | E29: =IF(Registre_Incidents!A14="","",Registre_Incidents!M14) | F29: =IF(Registre_Incidents!A14="","",Registre_Incidents!Q14) | G29: =IF(Registre_Incidents!A14="","",Registre_Incidents!T14) | H29: =IF(Registre_Incidents!A14="","",Registre_Incidents!P14)
A30: =IF(Registre_Incidents!A15="","",Registre_Incidents!A15) | B30: =IF(Registre_Incidents!A15="","",Registre_Incidents!B15) | C30: =IF(Registre_Incidents!A15="","",Registre_Incidents!E15) | D30: =IF(Registre_Incidents!A15="","",Registre_Incidents!L15) | E30: =IF(Registre_Incidents!A15="","",Registre_Incidents!M15) | F30: =IF(Registre_Incidents!A15="","",Registre_Incidents!Q15) | G30: =IF(Registre_Incidents!A15="","",Registre_Incidents!T15) | H30: =IF(Registre_Incidents!A15="","",Registre_Incidents!P15)

Sheet Guide_Demarrage
A1: Guide de démarrage — FAI Registre Incidents — DÉMO
A2: AVERTISSEMENT : ce classeur ne contient aucune donnée réelle. Il est prévu pour les essais et la formation.
A4: 1. Saisir | B4: Ajoutez une ligne dans Registre_Incidents à partir de la ligne 6. Les colonnes ID, SLA, échéance, durée et respect SLA sont calculées automatiquement.
A5: 2. Contrôler | B5: Utilisez les menus déroulants et les mises en forme rouges pour repérer les dépassements.
A6: 3. Piloter | B6: Consultez Tableau_de_bord pour les KPI et les répartitions.
A7: 4. Approfondir | B7: Utilisez l’interface web pour filtrer, modifier, valider et exporter les incidents.

Sheet Listes
A3: Statuts | B3: Priorités | C3: Catégories | D3: Sources | E3: Responsables | F3: Escalades
A4: Ouvert | B4: Critique | C4: Internet indisponible | D4: Appel | E4: NOC | F4: Non
A5: En cours | B5: Haute | C5: Débit lent / instable | D5: WhatsApp | E5: Support niveau 1 | F5: Oui - N2
A6: En attente client | B6: Moyenne | C6: Latence élevée | D6: Email | E6: Support niveau 2 | F6: Oui - Terrain
A7: Escaladé | B7: Basse | C7: Coupure intermittente | D7: Supervision UISP | E7: Équipe terrain | F7: Oui - Fournisseur
A8: Résolu | C8: Wi-Fi client | D8: Visite terrain | E8: Administration | F8: Oui - Direction
A9: Clôturé | C9: Équipement hors ligne | D9: Autre | E9: À assigner
C10: Problème alimentation
C11: Configuration / accès
C12: Facturation liée au service
C13: Autre

Sheet Parametres_SLA
A4: Priorité | B4: SLA heures
A5: Critique | B5: 4
A6: Haute | B6: 8
A7: Moyenne | B7: 24
A8: Basse | B8: 72
